{"messages": [{"role": "system", "content": "You are k8s-sre, a virtual Kubernetes engineer specialized on this cluster. Given the incident context, state the fix that worked and why, briefly."}, {"role": "user", "content": "[prod-east] alert_log: risk_level=CRITICAL pod=search-indexer-114efd24-182f5 ns=payments. kubernetes_pod_status: phase=Running ready=false restart_count=11. kubernetes_events: type=Warning reason=Unhealthy count=37 message=\"Readiness probe failed: HTTP probe failed with statuscode: 503\". What is happening and what is the fix?"}, {"role": "assistant", "content": "Unhealthy on search-indexer: the app answers 503 during warmup \u2014 lengthen initialDelaySeconds/failureThreshold on the readiness probe so the rollout stops flapping the endpoint in and out."}]}
{"messages": [{"role": "system", "content": "You are k8s-sre, a virtual Kubernetes engineer specialized on this cluster. Given the incident context, state the fix that worked and why, briefly."}, {"role": "user", "content": "[staging] alert_log: risk_level=CRITICAL pod=orders-consumer-3ad3b4b8-10791 ns=checkout. kubernetes_pod_status: phase=Running ready=false restart_count=39. kubernetes_events: type=Warning reason=FailedMount count=45 message=\"MountVolume.SetUp failed: secret not found\". What is happening and what is the fix?"}, {"role": "assistant", "content": "FailedMount on orders-consumer: the pod references a secret that is absent in this namespace \u2014 create/copy the secret or fix the volume's secretName; the kubelet mounts it on the next sync."}]}
{"messages": [{"role": "system", "content": "You are k8s-sre, a virtual Kubernetes engineer specialized on this cluster. Given the incident context, state the fix that worked and why, briefly."}, {"role": "user", "content": "[prod-east] alert_log: risk_level=CRITICAL pod=checkout-web-332c7147-1605c ns=inventory. kubernetes_pod_status: phase=Running ready=false restart_count=14. kubernetes_events: type=Warning reason=NodeNotReady count=13 message=\"Node is not ready: PLEG is not healthy\". What is happening and what is the fix?"}, {"role": "assistant", "content": "NodeNotReady on checkout-web: the node's runtime is wedged \u2014 cordon + drain it, restart the container runtime (or reboot), and uncordon once Ready; pods reschedule automatically."}]}
{"messages": [{"role": "system", "content": "You are k8s-sre, a virtual Kubernetes engineer specialized on this cluster. Given the incident context, state the fix that worked and why, briefly."}, {"role": "user", "content": "[staging] alert_log: risk_level=MEDIUM pod=search-indexer-5ab1064-8567 ns=payments. kubernetes_pod_status: phase=Running ready=false restart_count=8. kubernetes_events: type=Warning reason=Evicted count=32 message=\"The node was low on resource: ephemeral-storage\". What is happening and what is the fix?"}, {"role": "assistant", "content": "Evicted on search-indexer: ephemeral-storage pressure evicted the pod \u2014 clear image/log disk on the node and add an ephemeral-storage request to search-indexer so the scheduler places it where space exists."}]}
{"messages": [{"role": "system", "content": "You are k8s-sre, a virtual Kubernetes engineer specialized on this cluster. Given the incident context, state the fix that worked and why, briefly."}, {"role": "user", "content": "[prod-east] alert_log: risk_level=MEDIUM pod=checkout-web-1d0aa018-5e9 ns=inventory. kubernetes_pod_status: phase=Running ready=false restart_count=24. kubernetes_events: type=Warning reason=BackOff count=57 message=\"Back-off restarting failed container\". What is happening and what is the fix?"}, {"role": "assistant", "content": "CrashLoopBackOff on checkout-web: container exits on a failed dependency \u2014 read `kubectl logs --previous` for the exit reason, fix the dependency, then `kubectl rollout restart deploy/checkout-web`."}]}
{"messages": [{"role": "system", "content": "You are k8s-sre, a virtual Kubernetes engineer specialized on this cluster. Given the incident context, state the fix that worked and why, briefly."}, {"role": "user", "content": "[prod-east] alert_log: risk_level=HIGH pod=search-indexer-2c3e1ce-10dc7 ns=search. kubernetes_pod_status: phase=Running ready=false restart_count=18. kubernetes_events: type=Warning reason=OOMKilling count=24 message=\"Memory cgroup out of memory: Killed process\". What is happening and what is the fix?"}, {"role": "assistant", "content": "OOMKilled on search-indexer: memory limit is below the working set \u2014 raise the limit (and request) on search-indexer, then watch `restart_count` return to 0; if growth continues it is a leak, not sizing."}]}
{"messages": [{"role": "system", "content": "You are k8s-sre, a virtual Kubernetes engineer specialized on this cluster. Given the incident context, state the fix that worked and why, briefly."}, {"role": "user", "content": "[prod-east] alert_log: risk_level=MEDIUM pod=search-indexer-ce9c55a-9fbd ns=payments. kubernetes_pod_status: phase=Running ready=false restart_count=22. kubernetes_events: type=Warning reason=Failed count=30 message=\"Failed to pull image: manifest unknown\". What is happening and what is the fix?"}, {"role": "assistant", "content": "ImagePullBackOff on search-indexer: the tag referenced by the deployment does not exist in the registry \u2014 fix the image tag (or push the missing tag) and the kubelet retries automatically."}]}
{"messages": [{"role": "system", "content": "You are k8s-sre, a virtual Kubernetes engineer specialized on this cluster. Given the incident context, state the fix that worked and why, briefly."}, {"role": "user", "content": "[staging] alert_log: risk_level=CRITICAL pod=search-indexer-2b049fa4-5b15 ns=auth. kubernetes_pod_status: phase=Running ready=false restart_count=20. kubernetes_events: type=Warning reason=FailedScheduling count=6 message=\"0/6 nodes are available: insufficient memory\". What is happening and what is the fix?"}, {"role": "assistant", "content": "FailedScheduling on search-indexer: requests exceed free node capacity \u2014 right-size the requests of search-indexer or add a node; check `kubectl describe pod` Events for the exact predicate that failed."}]}
{"messages": [{"role": "system", "content": "You are k8s-sre, a virtual Kubernetes engineer specialized on this cluster. Given the incident context, state the fix that worked and why, briefly."}, {"role": "user", "content": "[prod-east] alert_log: risk_level=MEDIUM pod=search-indexer-12e055f-17756 ns=payments. kubernetes_pod_status: phase=Running ready=false restart_count=35. kubernetes_events: type=Warning reason=Unhealthy count=28 message=\"Readiness probe failed: HTTP probe failed with statuscode: 503\". What is happening and what is the fix?"}, {"role": "assistant", "content": "Unhealthy on search-indexer: the app answers 503 during warmup \u2014 lengthen initialDelaySeconds/failureThreshold on the readiness probe so the rollout stops flapping the endpoint in and out."}]}
{"messages": [{"role": "system", "content": "You are k8s-sre, a virtual Kubernetes engineer specialized on this cluster. Given the incident context, state the fix that worked and why, briefly."}, {"role": "user", "content": "[prod-west] alert_log: risk_level=MEDIUM pod=pricing-engine-6cd5046-1510f ns=checkout. kubernetes_pod_status: phase=Running ready=false restart_count=30. kubernetes_events: type=Warning reason=FailedMount count=67 message=\"MountVolume.SetUp failed: secret not found\". What is happening and what is the fix?"}, {"role": "assistant", "content": "FailedMount on pricing-engine: the pod references a secret that is absent in this namespace \u2014 create/copy the secret or fix the volume's secretName; the kubelet mounts it on the next sync."}]}
{"messages": [{"role": "system", "content": "You are k8s-sre, a virtual Kubernetes engineer specialized on this cluster. Given the incident context, state the fix that worked and why, briefly."}, {"role": "user", "content": "[prod-west] alert_log: risk_level=CRITICAL pod=orders-consumer-2c03f5ee-6e2c ns=search. kubernetes_pod_status: phase=Running ready=false restart_count=17. kubernetes_events: type=Warning reason=NodeNotReady count=29 message=\"Node is not ready: PLEG is not healthy\". What is happening and what is the fix?"}, {"role": "assistant", "content": "NodeNotReady on orders-consumer: the node's runtime is wedged \u2014 cordon + drain it, restart the container runtime (or reboot), and uncordon once Ready; pods reschedule automatically."}]}
{"messages": [{"role": "system", "content": "You are k8s-sre, a virtual Kubernetes engineer specialized on this cluster. Given the incident context, state the fix that worked and why, briefly."}, {"role": "user", "content": "[prod-west] alert_log: risk_level=HIGH pod=inventory-sync-37b1a08-4277 ns=auth. kubernetes_pod_status: phase=Running ready=false restart_count=3. kubernetes_events: type=Warning reason=Evicted count=84 message=\"The node was low on resource: ephemeral-storage\". What is happening and what is the fix?"}, {"role": "assistant", "content": "Evicted on inventory-sync: ephemeral-storage pressure evicted the pod \u2014 clear image/log disk on the node and add an ephemeral-storage request to inventory-sync so the scheduler places it where space exists."}]}
{"messages": [{"role": "system", "content": "You are k8s-sre, a virtual Kubernetes engineer specialized on this cluster. Given the incident context, state the fix that worked and why, briefly."}, {"role": "user", "content": "[prod-east] alert_log: risk_level=MEDIUM pod=search-indexer-38bb102-2b41 ns=auth. kubernetes_pod_status: phase=Running ready=false restart_count=27. kubernetes_events: type=Warning reason=BackOff count=89 message=\"Back-off restarting failed container\". What is happening and what is the fix?"}, {"role": "assistant", "content": "CrashLoopBackOff on search-indexer: container exits on a failed dependency \u2014 read `kubectl logs --previous` for the exit reason, fix the dependency, then `kubectl rollout restart deploy/search-indexer`."}]}
{"messages": [{"role": "system", "content": "You are k8s-sre, a virtual Kubernetes engineer specialized on this cluster. Given the incident context, state the fix that worked and why, briefly."}, {"role": "user", "content": "[prod-east] alert_log: risk_level=CRITICAL pod=search-indexer-2c54f5a7-960b ns=search. kubernetes_pod_status: phase=Running ready=false restart_count=5. kubernetes_events: type=Warning reason=OOMKilling count=27 message=\"Memory cgroup out of memory: Killed process\". What is happening and what is the fix?"}, {"role": "assistant", "content": "OOMKilled on search-indexer: memory limit is below the working set \u2014 raise the limit (and request) on search-indexer, then watch `restart_count` return to 0; if growth continues it is a leak, not sizing."}]}
{"messages": [{"role": "system", "content": "You are k8s-sre, a virtual Kubernetes engineer specialized on this cluster. Given the incident context, state the fix that worked and why, briefly."}, {"role": "user", "content": "[prod-west] alert_log: risk_level=CRITICAL pod=inventory-sync-3b5ac0-86c7 ns=inventory. kubernetes_pod_status: phase=Running ready=false restart_count=26. kubernetes_events: type=Warning reason=Failed count=74 message=\"Failed to pull image: manifest unknown\". What is happening and what is the fix?"}, {"role": "assistant", "content": "ImagePullBackOff on inventory-sync: the tag referenced by the deployment does not exist in the registry \u2014 fix the image tag (or push the missing tag) and the kubelet retries automatically."}]}
{"messages": [{"role": "system", "content": "You are k8s-sre, a virtual Kubernetes engineer specialized on this cluster. Given the incident context, state the fix that worked and why, briefly."}, {"role": "user", "content": "[prod-east] alert_log: risk_level=CRITICAL pod=notify-worker-38790ded-9e7d ns=checkout. kubernetes_pod_status: phase=Running ready=false restart_count=16. kubernetes_events: type=Warning reason=FailedScheduling count=27 message=\"0/6 nodes are available: insufficient memory\". What is happening and what is the fix?"}, {"role": "assistant", "content": "FailedScheduling on notify-worker: requests exceed free node capacity \u2014 right-size the requests of notify-worker or add a node; check `kubectl describe pod` Events for the exact predicate that failed."}]}
{"messages": [{"role": "system", "content": "You are k8s-sre, a virtual Kubernetes engineer specialized on this cluster. Given the incident context, state the fix that worked and why, briefly."}, {"role": "user", "content": "[prod-west] alert_log: risk_level=MEDIUM pod=payments-api-55e7682-f304 ns=inventory. kubernetes_pod_status: phase=Running ready=false restart_count=20. kubernetes_events: type=Warning reason=Unhealthy count=87 message=\"Readiness probe failed: HTTP probe failed with statuscode: 503\". What is happening and what is the fix?"}, {"role": "assistant", "content": "Unhealthy on payments-api: the app answers 503 during warmup \u2014 lengthen initialDelaySeconds/failureThreshold on the readiness probe so the rollout stops flapping the endpoint in and out."}]}
{"messages": [{"role": "system", "content": "You are k8s-sre, a virtual Kubernetes engineer specialized on this cluster. Given the incident context, state the fix that worked and why, briefly."}, {"role": "user", "content": "[staging] alert_log: risk_level=CRITICAL pod=auth-gateway-31ade27b-288 ns=checkout. kubernetes_pod_status: phase=Running ready=false restart_count=8. kubernetes_events: type=Warning reason=FailedMount count=15 message=\"MountVolume.SetUp failed: secret not found\". What is happening and what is the fix?"}, {"role": "assistant", "content": "FailedMount on auth-gateway: the pod references a secret that is absent in this namespace \u2014 create/copy the secret or fix the volume's secretName; the kubelet mounts it on the next sync."}]}
{"messages": [{"role": "system", "content": "You are k8s-sre, a virtual Kubernetes engineer specialized on this cluster. Given the incident context, state the fix that worked and why, briefly."}, {"role": "user", "content": "[staging] alert_log: risk_level=CRITICAL pod=inventory-sync-2aaabe0-c9b7 ns=auth. kubernetes_pod_status: phase=Running ready=false restart_count=4. kubernetes_events: type=Warning reason=NodeNotReady count=42 message=\"Node is not ready: PLEG is not healthy\". What is happening and what is the fix?"}, {"role": "assistant", "content": "NodeNotReady on inventory-sync: the node's runtime is wedged \u2014 cordon + drain it, restart the container runtime (or reboot), and uncordon once Ready; pods reschedule automatically."}]}
{"messages": [{"role": "system", "content": "You are k8s-sre, a virtual Kubernetes engineer specialized on this cluster. Given the incident context, state the fix that worked and why, briefly."}, {"role": "user", "content": "[staging] alert_log: risk_level=MEDIUM pod=auth-gateway-21de3dd0-18046 ns=payments. kubernetes_pod_status: phase=Running ready=false restart_count=12. kubernetes_events: type=Warning reason=Evicted count=80 message=\"The node was low on resource: ephemeral-storage\". What is happening and what is the fix?"}, {"role": "assistant", "content": "Evicted on auth-gateway: ephemeral-storage pressure evicted the pod \u2014 clear image/log disk on the node and add an ephemeral-storage request to auth-gateway so the scheduler places it where space exists."}]}
{"messages": [{"role": "system", "content": "You are k8s-sre, a virtual Kubernetes engineer specialized on this cluster. Given the incident context, state the fix that worked and why, briefly."}, {"role": "user", "content": "[staging] alert_log: risk_level=MEDIUM pod=orders-consumer-1fa0d241-4c86 ns=inventory. kubernetes_pod_status: phase=Running ready=false restart_count=21. kubernetes_events: type=Warning reason=BackOff count=83 message=\"Back-off restarting failed container\". What is happening and what is the fix?"}, {"role": "assistant", "content": "CrashLoopBackOff on orders-consumer: container exits on a failed dependency \u2014 read `kubectl logs --previous` for the exit reason, fix the dependency, then `kubectl rollout restart deploy/orders-consumer`."}]}
{"messages": [{"role": "system", "content": "You are k8s-sre, a virtual Kubernetes engineer specialized on this cluster. Given the incident context, state the fix that worked and why, briefly."}, {"role": "user", "content": "[staging] alert_log: risk_level=MEDIUM pod=inventory-sync-39159567-106a5 ns=payments. kubernetes_pod_status: phase=Running ready=false restart_count=30. kubernetes_events: type=Warning reason=OOMKilling count=68 message=\"Memory cgroup out of memory: Killed process\". What is happening and what is the fix?"}, {"role": "assistant", "content": "OOMKilled on inventory-sync: memory limit is below the working set \u2014 raise the limit (and request) on inventory-sync, then watch `restart_count` return to 0; if growth continues it is a leak, not sizing."}]}
{"messages": [{"role": "system", "content": "You are k8s-sre, a virtual Kubernetes engineer specialized on this cluster. Given the incident context, state the fix that worked and why, briefly."}, {"role": "user", "content": "[staging] alert_log: risk_level=HIGH pod=inventory-sync-2461f7d0-83b ns=search. kubernetes_pod_status: phase=Running ready=false restart_count=17. kubernetes_events: type=Warning reason=Failed count=7 message=\"Failed to pull image: manifest unknown\". What is happening and what is the fix?"}, {"role": "assistant", "content": "ImagePullBackOff on inventory-sync: the tag referenced by the deployment does not exist in the registry \u2014 fix the image tag (or push the missing tag) and the kubelet retries automatically."}]}
{"messages": [{"role": "system", "content": "You are k8s-sre, a virtual Kubernetes engineer specialized on this cluster. Given the incident context, state the fix that worked and why, briefly."}, {"role": "user", "content": "[staging] alert_log: risk_level=CRITICAL pod=payments-api-1715d4ca-35b7 ns=checkout. kubernetes_pod_status: phase=Running ready=false restart_count=27. kubernetes_events: type=Warning reason=FailedScheduling count=75 message=\"0/6 nodes are available: insufficient memory\". What is happening and what is the fix?"}, {"role": "assistant", "content": "FailedScheduling on payments-api: requests exceed free node capacity \u2014 right-size the requests of payments-api or add a node; check `kubectl describe pod` Events for the exact predicate that failed."}]}
{"messages": [{"role": "system", "content": "You are k8s-sre, a virtual Kubernetes engineer specialized on this cluster. Given the incident context, state the fix that worked and why, briefly."}, {"role": "user", "content": "[prod-east] alert_log: risk_level=CRITICAL pod=payments-api-28141826-11019 ns=notifications. kubernetes_pod_status: phase=Running ready=false restart_count=18. kubernetes_events: type=Warning reason=Unhealthy count=37 message=\"Readiness probe failed: HTTP probe failed with statuscode: 503\". What is happening and what is the fix?"}, {"role": "assistant", "content": "Unhealthy on payments-api: the app answers 503 during warmup \u2014 lengthen initialDelaySeconds/failureThreshold on the readiness probe so the rollout stops flapping the endpoint in and out."}]}
{"messages": [{"role": "system", "content": "You are k8s-sre, a virtual Kubernetes engineer specialized on this cluster. Given the incident context, state the fix that worked and why, briefly."}, {"role": "user", "content": "[prod-east] alert_log: risk_level=HIGH pod=payments-api-2fe3946a-10185 ns=auth. kubernetes_pod_status: phase=Running ready=false restart_count=37. kubernetes_events: type=Warning reason=FailedMount count=88 message=\"MountVolume.SetUp failed: secret not found\". What is happening and what is the fix?"}, {"role": "assistant", "content": "FailedMount on payments-api: the pod references a secret that is absent in this namespace \u2014 create/copy the secret or fix the volume's secretName; the kubelet mounts it on the next sync."}]}
{"messages": [{"role": "system", "content": "You are k8s-sre, a virtual Kubernetes engineer specialized on this cluster. Given the incident context, state the fix that worked and why, briefly."}, {"role": "user", "content": "[staging] alert_log: risk_level=CRITICAL pod=checkout-web-1e53b249-811f ns=notifications. kubernetes_pod_status: phase=Running ready=false restart_count=7. kubernetes_events: type=Warning reason=NodeNotReady count=34 message=\"Node is not ready: PLEG is not healthy\". What is happening and what is the fix?"}, {"role": "assistant", "content": "NodeNotReady on checkout-web: the node's runtime is wedged \u2014 cordon + drain it, restart the container runtime (or reboot), and uncordon once Ready; pods reschedule automatically."}]}
{"messages": [{"role": "system", "content": "You are k8s-sre, a virtual Kubernetes engineer specialized on this cluster. Given the incident context, state the fix that worked and why, briefly."}, {"role": "user", "content": "[staging] alert_log: risk_level=CRITICAL pod=auth-gateway-29987d8b-ebb1 ns=checkout. kubernetes_pod_status: phase=Running ready=false restart_count=34. kubernetes_events: type=Warning reason=Evicted count=13 message=\"The node was low on resource: ephemeral-storage\". What is happening and what is the fix?"}, {"role": "assistant", "content": "Evicted on auth-gateway: ephemeral-storage pressure evicted the pod \u2014 clear image/log disk on the node and add an ephemeral-storage request to auth-gateway so the scheduler places it where space exists."}]}
{"messages": [{"role": "system", "content": "You are k8s-sre, a virtual Kubernetes engineer specialized on this cluster. Given the incident context, state the fix that worked and why, briefly."}, {"role": "user", "content": "[prod-west] alert_log: risk_level=HIGH pod=pricing-engine-311609cb-17ef ns=notifications. kubernetes_pod_status: phase=Running ready=false restart_count=15. kubernetes_events: type=Warning reason=BackOff count=80 message=\"Back-off restarting failed container\". What is happening and what is the fix?"}, {"role": "assistant", "content": "CrashLoopBackOff on pricing-engine: container exits on a failed dependency \u2014 read `kubectl logs --previous` for the exit reason, fix the dependency, then `kubectl rollout restart deploy/pricing-engine`."}]}
{"messages": [{"role": "system", "content": "You are k8s-sre, a virtual Kubernetes engineer specialized on this cluster. Given the incident context, state the fix that worked and why, briefly."}, {"role": "user", "content": "[prod-west] alert_log: risk_level=MEDIUM pod=inventory-sync-29b2bd28-17c86 ns=inventory. kubernetes_pod_status: phase=Running ready=false restart_count=22. kubernetes_events: type=Warning reason=OOMKilling count=76 message=\"Memory cgroup out of memory: Killed process\". What is happening and what is the fix?"}, {"role": "assistant", "content": "OOMKilled on inventory-sync: memory limit is below the working set \u2014 raise the limit (and request) on inventory-sync, then watch `restart_count` return to 0; if growth continues it is a leak, not sizing."}]}
