{"messages": [{"role": "system", "content": "You are k8s-sre, a virtual Kubernetes engineer specialized on this cluster. Given the incident context, state the fix that worked and why, briefly."}, {"role": "user", "content": "[prod-west] alert_log: risk_level=MEDIUM pod=notify-worker-29a8e914-18b8 ns=checkout. kubernetes_pod_status: phase=Running ready=false restart_count=7. kubernetes_events: type=Warning reason=BackOff count=16 message=\"Back-off restarting failed container\". What is happening and what is the fix?"}, {"role": "assistant", "content": "CrashLoopBackOff on notify-worker: container exits on a failed dependency \u2014 read `kubectl logs --previous` for the exit reason, fix the dependency, then `kubectl rollout restart deploy/notify-worker`."}]}
{"messages": [{"role": "system", "content": "You are k8s-sre, a virtual Kubernetes engineer specialized on this cluster. Given the incident context, state the fix that worked and why, briefly."}, {"role": "user", "content": "[prod-east] alert_log: risk_level=HIGH pod=notify-worker-3a389765-103ce ns=search. kubernetes_pod_status: phase=Running ready=false restart_count=16. kubernetes_events: type=Warning reason=OOMKilling count=15 message=\"Memory cgroup out of memory: Killed process\". What is happening and what is the fix?"}, {"role": "assistant", "content": "OOMKilled on notify-worker: memory limit is below the working set \u2014 raise the limit (and request) on notify-worker, then watch `restart_count` return to 0; if growth continues it is a leak, not sizing."}]}
{"messages": [{"role": "system", "content": "You are k8s-sre, a virtual Kubernetes engineer specialized on this cluster. Given the incident context, state the fix that worked and why, briefly."}, {"role": "user", "content": "[prod-east] alert_log: risk_level=CRITICAL pod=orders-consumer-f6705c9-2e71 ns=auth. kubernetes_pod_status: phase=Running ready=false restart_count=38. kubernetes_events: type=Warning reason=Failed count=11 message=\"Failed to pull image: manifest unknown\". What is happening and what is the fix?"}, {"role": "assistant", "content": "ImagePullBackOff on orders-consumer: the tag referenced by the deployment does not exist in the registry \u2014 fix the image tag (or push the missing tag) and the kubelet retries automatically."}]}
{"messages": [{"role": "system", "content": "You are k8s-sre, a virtual Kubernetes engineer specialized on this cluster. Given the incident context, state the fix that worked and why, briefly."}, {"role": "user", "content": "[staging] alert_log: risk_level=MEDIUM pod=checkout-web-2827ddad-12a7e ns=checkout. kubernetes_pod_status: phase=Running ready=false restart_count=6. kubernetes_events: type=Warning reason=FailedScheduling count=78 message=\"0/6 nodes are available: insufficient memory\". What is happening and what is the fix?"}, {"role": "assistant", "content": "FailedScheduling on checkout-web: requests exceed free node capacity \u2014 right-size the requests of checkout-web or add a node; check `kubectl describe pod` Events for the exact predicate that failed."}]}
{"messages": [{"role": "system", "content": "You are k8s-sre, a virtual Kubernetes engineer specialized on this cluster. Given the incident context, state the fix that worked and why, briefly."}, {"role": "user", "content": "[prod-east] alert_log: risk_level=CRITICAL pod=orders-consumer-2fb35ec-11d03 ns=payments. kubernetes_pod_status: phase=Running ready=false restart_count=11. kubernetes_events: type=Warning reason=Unhealthy count=57 message=\"Readiness probe failed: HTTP probe failed with statuscode: 503\". What is happening and what is the fix?"}, {"role": "assistant", "content": "Unhealthy on orders-consumer: the app answers 503 during warmup \u2014 lengthen initialDelaySeconds/failureThreshold on the readiness probe so the rollout stops flapping the endpoint in and out."}]}
{"messages": [{"role": "system", "content": "You are k8s-sre, a virtual Kubernetes engineer specialized on this cluster. Given the incident context, state the fix that worked and why, briefly."}, {"role": "user", "content": "[prod-east] alert_log: risk_level=MEDIUM pod=inventory-sync-2489d996-9df1 ns=search. kubernetes_pod_status: phase=Running ready=false restart_count=38. kubernetes_events: type=Warning reason=FailedMount count=27 message=\"MountVolume.SetUp failed: secret not found\". What is happening and what is the fix?"}, {"role": "assistant", "content": "FailedMount on inventory-sync: the pod references a secret that is absent in this namespace \u2014 create/copy the secret or fix the volume's secretName; the kubelet mounts it on the next sync."}]}
{"messages": [{"role": "system", "content": "You are k8s-sre, a virtual Kubernetes engineer specialized on this cluster. Given the incident context, state the fix that worked and why, briefly."}, {"role": "user", "content": "[staging] alert_log: risk_level=HIGH pod=checkout-web-28e3f551-6030 ns=search. kubernetes_pod_status: phase=Running ready=false restart_count=26. kubernetes_events: type=Warning reason=NodeNotReady count=74 message=\"Node is not ready: PLEG is not healthy\". What is happening and what is the fix?"}, {"role": "assistant", "content": "NodeNotReady on checkout-web: the node's runtime is wedged \u2014 cordon + drain it, restart the container runtime (or reboot), and uncordon once Ready; pods reschedule automatically."}]}
{"messages": [{"role": "system", "content": "You are k8s-sre, a virtual Kubernetes engineer specialized on this cluster. Given the incident context, state the fix that worked and why, briefly."}, {"role": "user", "content": "[prod-east] alert_log: risk_level=MEDIUM pod=checkout-web-279dda6c-6973 ns=search. kubernetes_pod_status: phase=Running ready=false restart_count=34. kubernetes_events: type=Warning reason=Evicted count=72 message=\"The node was low on resource: ephemeral-storage\". What is happening and what is the fix?"}, {"role": "assistant", "content": "Evicted on checkout-web: ephemeral-storage pressure evicted the pod \u2014 clear image/log disk on the node and add an ephemeral-storage request to checkout-web so the scheduler places it where space exists."}]}
{"messages": [{"role": "system", "content": "You are k8s-sre, a virtual Kubernetes engineer specialized on this cluster. Given the incident context, state the fix that worked and why, briefly."}, {"role": "user", "content": "[prod-west] alert_log: risk_level=CRITICAL pod=orders-consumer-2579d874-e807 ns=inventory. kubernetes_pod_status: phase=Running ready=false restart_count=26. kubernetes_events: type=Warning reason=BackOff count=35 message=\"Back-off restarting failed container\". What is happening and what is the fix?"}, {"role": "assistant", "content": "CrashLoopBackOff on orders-consumer: container exits on a failed dependency \u2014 read `kubectl logs --previous` for the exit reason, fix the dependency, then `kubectl rollout restart deploy/orders-consumer`."}]}
{"messages": [{"role": "system", "content": "You are k8s-sre, a virtual Kubernetes engineer specialized on this cluster. Given the incident context, state the fix that worked and why, briefly."}, {"role": "user", "content": "[prod-east] alert_log: risk_level=MEDIUM pod=inventory-sync-53d1ccf-1261a ns=notifications. kubernetes_pod_status: phase=Running ready=false restart_count=22. kubernetes_events: type=Warning reason=OOMKilling count=67 message=\"Memory cgroup out of memory: Killed process\". What is happening and what is the fix?"}, {"role": "assistant", "content": "OOMKilled on inventory-sync: memory limit is below the working set \u2014 raise the limit (and request) on inventory-sync, then watch `restart_count` return to 0; if growth continues it is a leak, not sizing."}]}
{"messages": [{"role": "system", "content": "You are k8s-sre, a virtual Kubernetes engineer specialized on this cluster. Given the incident context, state the fix that worked and why, briefly."}, {"role": "user", "content": "[prod-west] alert_log: risk_level=HIGH pod=notify-worker-126d9282-137c9 ns=notifications. kubernetes_pod_status: phase=Running ready=false restart_count=7. kubernetes_events: type=Warning reason=Failed count=69 message=\"Failed to pull image: manifest unknown\". What is happening and what is the fix?"}, {"role": "assistant", "content": "ImagePullBackOff on notify-worker: the tag referenced by the deployment does not exist in the registry \u2014 fix the image tag (or push the missing tag) and the kubelet retries automatically."}]}
{"messages": [{"role": "system", "content": "You are k8s-sre, a virtual Kubernetes engineer specialized on this cluster. Given the incident context, state the fix that worked and why, briefly."}, {"role": "user", "content": "[prod-west] alert_log: risk_level=HIGH pod=orders-consumer-9ba1d55-fa59 ns=checkout. kubernetes_pod_status: phase=Running ready=false restart_count=29. kubernetes_events: type=Warning reason=FailedScheduling count=89 message=\"0/6 nodes are available: insufficient memory\". What is happening and what is the fix?"}, {"role": "assistant", "content": "FailedScheduling on orders-consumer: requests exceed free node capacity \u2014 right-size the requests of orders-consumer or add a node; check `kubectl describe pod` Events for the exact predicate that failed."}]}
{"messages": [{"role": "system", "content": "You are k8s-sre, a virtual Kubernetes engineer specialized on this cluster. Given the incident context, state the fix that worked and why, briefly."}, {"role": "user", "content": "[staging] alert_log: risk_level=MEDIUM pod=checkout-web-328084d7-a0a3 ns=search. kubernetes_pod_status: phase=Running ready=false restart_count=24. kubernetes_events: type=Warning reason=Unhealthy count=48 message=\"Readiness probe failed: HTTP probe failed with statuscode: 503\". What is happening and what is the fix?"}, {"role": "assistant", "content": "Unhealthy on checkout-web: the app answers 503 during warmup \u2014 lengthen initialDelaySeconds/failureThreshold on the readiness probe so the rollout stops flapping the endpoint in and out."}]}
{"messages": [{"role": "system", "content": "You are k8s-sre, a virtual Kubernetes engineer specialized on this cluster. Given the incident context, state the fix that worked and why, briefly."}, {"role": "user", "content": "[prod-west] alert_log: risk_level=CRITICAL pod=pricing-engine-4669cb4-2feb ns=search. kubernetes_pod_status: phase=Running ready=false restart_count=20. kubernetes_events: type=Warning reason=FailedMount count=89 message=\"MountVolume.SetUp failed: secret not found\". What is happening and what is the fix?"}, {"role": "assistant", "content": "FailedMount on pricing-engine: the pod references a secret that is absent in this namespace \u2014 create/copy the secret or fix the volume's secretName; the kubelet mounts it on the next sync."}]}
{"messages": [{"role": "system", "content": "You are k8s-sre, a virtual Kubernetes engineer specialized on this cluster. Given the incident context, state the fix that worked and why, briefly."}, {"role": "user", "content": "[staging] alert_log: risk_level=MEDIUM pod=checkout-web-2ce53ecd-9e84 ns=payments. kubernetes_pod_status: phase=Running ready=false restart_count=39. kubernetes_events: type=Warning reason=NodeNotReady count=61 message=\"Node is not ready: PLEG is not healthy\". What is happening and what is the fix?"}, {"role": "assistant", "content": "NodeNotReady on checkout-web: the node's runtime is wedged \u2014 cordon + drain it, restart the container runtime (or reboot), and uncordon once Ready; pods reschedule automatically."}]}
{"messages": [{"role": "system", "content": "You are k8s-sre, a virtual Kubernetes engineer specialized on this cluster. Given the incident context, state the fix that worked and why, briefly."}, {"role": "user", "content": "[prod-west] alert_log: risk_level=HIGH pod=search-indexer-38c544a2-15659 ns=notifications. kubernetes_pod_status: phase=Running ready=false restart_count=25. kubernetes_events: type=Warning reason=Evicted count=63 message=\"The node was low on resource: ephemeral-storage\". What is happening and what is the fix?"}, {"role": "assistant", "content": "Evicted on search-indexer: ephemeral-storage pressure evicted the pod \u2014 clear image/log disk on the node and add an ephemeral-storage request to search-indexer so the scheduler places it where space exists."}]}
{"messages": [{"role": "system", "content": "You are k8s-sre, a virtual Kubernetes engineer specialized on this cluster. Given the incident context, state the fix that worked and why, briefly."}, {"role": "user", "content": "[staging] alert_log: risk_level=HIGH pod=notify-worker-77e7f5e-fcc5 ns=checkout. kubernetes_pod_status: phase=Running ready=false restart_count=6. kubernetes_events: type=Warning reason=BackOff count=40 message=\"Back-off restarting failed container\". What is happening and what is the fix?"}, {"role": "assistant", "content": "CrashLoopBackOff on notify-worker: container exits on a failed dependency \u2014 read `kubectl logs --previous` for the exit reason, fix the dependency, then `kubectl rollout restart deploy/notify-worker`."}]}
{"messages": [{"role": "system", "content": "You are k8s-sre, a virtual Kubernetes engineer specialized on this cluster. Given the incident context, state the fix that worked and why, briefly."}, {"role": "user", "content": "[prod-east] alert_log: risk_level=HIGH pod=inventory-sync-197727d4-c82a ns=notifications. kubernetes_pod_status: phase=Running ready=false restart_count=34. kubernetes_events: type=Warning reason=OOMKilling count=25 message=\"Memory cgroup out of memory: Killed process\". What is happening and what is the fix?"}, {"role": "assistant", "content": "OOMKilled on inventory-sync: memory limit is below the working set \u2014 raise the limit (and request) on inventory-sync, then watch `restart_count` return to 0; if growth continues it is a leak, not sizing."}]}
{"messages": [{"role": "system", "content": "You are k8s-sre, a virtual Kubernetes engineer specialized on this cluster. Given the incident context, state the fix that worked and why, briefly."}, {"role": "user", "content": "[staging] alert_log: risk_level=MEDIUM pod=pricing-engine-11c81dc7-461b ns=auth. kubernetes_pod_status: phase=Running ready=false restart_count=30. kubernetes_events: type=Warning reason=Failed count=39 message=\"Failed to pull image: manifest unknown\". What is happening and what is the fix?"}, {"role": "assistant", "content": "ImagePullBackOff on pricing-engine: the tag referenced by the deployment does not exist in the registry \u2014 fix the image tag (or push the missing tag) and the kubelet retries automatically."}]}
{"messages": [{"role": "system", "content": "You are k8s-sre, a virtual Kubernetes engineer specialized on this cluster. Given the incident context, state the fix that worked and why, briefly."}, {"role": "user", "content": "[staging] alert_log: risk_level=HIGH pod=orders-consumer-38969d81-c2c9 ns=inventory. kubernetes_pod_status: phase=Running ready=false restart_count=17. kubernetes_events: type=Warning reason=FailedScheduling count=14 message=\"0/6 nodes are available: insufficient memory\". What is happening and what is the fix?"}, {"role": "assistant", "content": "FailedScheduling on orders-consumer: requests exceed free node capacity \u2014 right-size the requests of orders-consumer or add a node; check `kubectl describe pod` Events for the exact predicate that failed."}]}
{"messages": [{"role": "system", "content": "You are k8s-sre, a virtual Kubernetes engineer specialized on this cluster. Given the incident context, state the fix that worked and why, briefly."}, {"role": "user", "content": "[prod-east] alert_log: risk_level=CRITICAL pod=inventory-sync-2a252322-7777 ns=checkout. kubernetes_pod_status: phase=Running ready=false restart_count=3. kubernetes_events: type=Warning reason=Unhealthy count=79 message=\"Readiness probe failed: HTTP probe failed with statuscode: 503\". What is happening and what is the fix?"}, {"role": "assistant", "content": "Unhealthy on inventory-sync: the app answers 503 during warmup \u2014 lengthen initialDelaySeconds/failureThreshold on the readiness probe so the rollout stops flapping the endpoint in and out."}]}
{"messages": [{"role": "system", "content": "You are k8s-sre, a virtual Kubernetes engineer specialized on this cluster. Given the incident context, state the fix that worked and why, briefly."}, {"role": "user", "content": "[prod-west] alert_log: risk_level=MEDIUM pod=inventory-sync-4311d6-4a96 ns=inventory. kubernetes_pod_status: phase=Running ready=false restart_count=29. kubernetes_events: type=Warning reason=FailedMount count=51 message=\"MountVolume.SetUp failed: secret not found\". What is happening and what is the fix?"}, {"role": "assistant", "content": "FailedMount on inventory-sync: the pod references a secret that is absent in this namespace \u2014 create/copy the secret or fix the volume's secretName; the kubelet mounts it on the next sync."}]}
{"messages": [{"role": "system", "content": "You are k8s-sre, a virtual Kubernetes engineer specialized on this cluster. Given the incident context, state the fix that worked and why, briefly."}, {"role": "user", "content": "[staging] alert_log: risk_level=CRITICAL pod=notify-worker-36fd2a2c-107ee ns=checkout. kubernetes_pod_status: phase=Running ready=false restart_count=6. kubernetes_events: type=Warning reason=NodeNotReady count=75 message=\"Node is not ready: PLEG is not healthy\". What is happening and what is the fix?"}, {"role": "assistant", "content": "NodeNotReady on notify-worker: the node's runtime is wedged \u2014 cordon + drain it, restart the container runtime (or reboot), and uncordon once Ready; pods reschedule automatically."}]}
{"messages": [{"role": "system", "content": "You are k8s-sre, a virtual Kubernetes engineer specialized on this cluster. Given the incident context, state the fix that worked and why, briefly."}, {"role": "user", "content": "[prod-west] alert_log: risk_level=MEDIUM pod=orders-consumer-1939432b-3502 ns=auth. kubernetes_pod_status: phase=Running ready=false restart_count=33. kubernetes_events: type=Warning reason=Evicted count=55 message=\"The node was low on resource: ephemeral-storage\". What is happening and what is the fix?"}, {"role": "assistant", "content": "Evicted on orders-consumer: ephemeral-storage pressure evicted the pod \u2014 clear image/log disk on the node and add an ephemeral-storage request to orders-consumer so the scheduler places it where space exists."}]}
{"messages": [{"role": "system", "content": "You are k8s-sre, a virtual Kubernetes engineer specialized on this cluster. Given the incident context, state the fix that worked and why, briefly."}, {"role": "user", "content": "[prod-east] alert_log: risk_level=HIGH pod=payments-api-d5c6042-e199 ns=checkout. kubernetes_pod_status: phase=Running ready=false restart_count=13. kubernetes_events: type=Warning reason=BackOff count=47 message=\"Back-off restarting failed container\". What is happening and what is the fix?"}, {"role": "assistant", "content": "CrashLoopBackOff on payments-api: container exits on a failed dependency \u2014 read `kubectl logs --previous` for the exit reason, fix the dependency, then `kubectl rollout restart deploy/payments-api`."}]}
{"messages": [{"role": "system", "content": "You are k8s-sre, a virtual Kubernetes engineer specialized on this cluster. Given the incident context, state the fix that worked and why, briefly."}, {"role": "user", "content": "[prod-east] alert_log: risk_level=HIGH pod=payments-api-24462ec5-4d72 ns=payments. kubernetes_pod_status: phase=Running ready=false restart_count=37. kubernetes_events: type=Warning reason=OOMKilling count=50 message=\"Memory cgroup out of memory: Killed process\". What is happening and what is the fix?"}, {"role": "assistant", "content": "OOMKilled on payments-api: memory limit is below the working set \u2014 raise the limit (and request) on payments-api, then watch `restart_count` return to 0; if growth continues it is a leak, not sizing."}]}
{"messages": [{"role": "system", "content": "You are k8s-sre, a virtual Kubernetes engineer specialized on this cluster. Given the incident context, state the fix that worked and why, briefly."}, {"role": "user", "content": "[prod-east] alert_log: risk_level=MEDIUM pod=payments-api-274ce807-c0a1 ns=payments. kubernetes_pod_status: phase=Running ready=false restart_count=12. kubernetes_events: type=Warning reason=Failed count=36 message=\"Failed to pull image: manifest unknown\". What is happening and what is the fix?"}, {"role": "assistant", "content": "ImagePullBackOff on payments-api: the tag referenced by the deployment does not exist in the registry \u2014 fix the image tag (or push the missing tag) and the kubelet retries automatically."}]}
{"messages": [{"role": "system", "content": "You are k8s-sre, a virtual Kubernetes engineer specialized on this cluster. Given the incident context, state the fix that worked and why, briefly."}, {"role": "user", "content": "[prod-west] alert_log: risk_level=CRITICAL pod=notify-worker-1e587f64-3ee5 ns=search. kubernetes_pod_status: phase=Running ready=false restart_count=10. kubernetes_events: type=Warning reason=FailedScheduling count=63 message=\"0/6 nodes are available: insufficient memory\". What is happening and what is the fix?"}, {"role": "assistant", "content": "FailedScheduling on notify-worker: requests exceed free node capacity \u2014 right-size the requests of notify-worker or add a node; check `kubectl describe pod` Events for the exact predicate that failed."}]}
{"messages": [{"role": "system", "content": "You are k8s-sre, a virtual Kubernetes engineer specialized on this cluster. Given the incident context, state the fix that worked and why, briefly."}, {"role": "user", "content": "[prod-west] alert_log: risk_level=MEDIUM pod=pricing-engine-57f2267-49c9 ns=auth. kubernetes_pod_status: phase=Running ready=false restart_count=9. kubernetes_events: type=Warning reason=Unhealthy count=47 message=\"Readiness probe failed: HTTP probe failed with statuscode: 503\". What is happening and what is the fix?"}, {"role": "assistant", "content": "Unhealthy on pricing-engine: the app answers 503 during warmup \u2014 lengthen initialDelaySeconds/failureThreshold on the readiness probe so the rollout stops flapping the endpoint in and out."}]}
{"messages": [{"role": "system", "content": "You are k8s-sre, a virtual Kubernetes engineer specialized on this cluster. Given the incident context, state the fix that worked and why, briefly."}, {"role": "user", "content": "[staging] alert_log: risk_level=HIGH pod=search-indexer-a55029b-1085c ns=auth. kubernetes_pod_status: phase=Running ready=false restart_count=4. kubernetes_events: type=Warning reason=FailedMount count=71 message=\"MountVolume.SetUp failed: secret not found\". What is happening and what is the fix?"}, {"role": "assistant", "content": "FailedMount on search-indexer: the pod references a secret that is absent in this namespace \u2014 create/copy the secret or fix the volume's secretName; the kubelet mounts it on the next sync."}]}
{"messages": [{"role": "system", "content": "You are k8s-sre, a virtual Kubernetes engineer specialized on this cluster. Given the incident context, state the fix that worked and why, briefly."}, {"role": "user", "content": "[staging] alert_log: risk_level=CRITICAL pod=notify-worker-22c35642-dd8 ns=checkout. kubernetes_pod_status: phase=Running ready=false restart_count=36. kubernetes_events: type=Warning reason=NodeNotReady count=86 message=\"Node is not ready: PLEG is not healthy\". What is happening and what is the fix?"}, {"role": "assistant", "content": "NodeNotReady on notify-worker: the node's runtime is wedged \u2014 cordon + drain it, restart the container runtime (or reboot), and uncordon once Ready; pods reschedule automatically."}]}
{"messages": [{"role": "system", "content": "You are k8s-sre, a virtual Kubernetes engineer specialized on this cluster. Given the incident context, state the fix that worked and why, briefly."}, {"role": "user", "content": "[prod-west] alert_log: risk_level=CRITICAL pod=checkout-web-212d6a06-bbc0 ns=notifications. kubernetes_pod_status: phase=Running ready=false restart_count=13. kubernetes_events: type=Warning reason=Evicted count=32 message=\"The node was low on resource: ephemeral-storage\". What is happening and what is the fix?"}, {"role": "assistant", "content": "Evicted on checkout-web: ephemeral-storage pressure evicted the pod \u2014 clear image/log disk on the node and add an ephemeral-storage request to checkout-web so the scheduler places it where space exists."}]}
{"messages": [{"role": "system", "content": "You are k8s-sre, a virtual Kubernetes engineer specialized on this cluster. Given the incident context, state the fix that worked and why, briefly."}, {"role": "user", "content": "[prod-east] alert_log: risk_level=HIGH pod=notify-worker-273f2194-18442 ns=notifications. kubernetes_pod_status: phase=Running ready=false restart_count=15. kubernetes_events: type=Warning reason=BackOff count=55 message=\"Back-off restarting failed container\". What is happening and what is the fix?"}, {"role": "assistant", "content": "CrashLoopBackOff on notify-worker: container exits on a failed dependency \u2014 read `kubectl logs --previous` for the exit reason, fix the dependency, then `kubectl rollout restart deploy/notify-worker`."}]}
{"messages": [{"role": "system", "content": "You are k8s-sre, a virtual Kubernetes engineer specialized on this cluster. Given the incident context, state the fix that worked and why, briefly."}, {"role": "user", "content": "[staging] alert_log: risk_level=HIGH pod=auth-gateway-1f89bcda-b60c ns=checkout. kubernetes_pod_status: phase=Running ready=false restart_count=4. kubernetes_events: type=Warning reason=OOMKilling count=39 message=\"Memory cgroup out of memory: Killed process\". What is happening and what is the fix?"}, {"role": "assistant", "content": "OOMKilled on auth-gateway: memory limit is below the working set \u2014 raise the limit (and request) on auth-gateway, then watch `restart_count` return to 0; if growth continues it is a leak, not sizing."}]}
{"messages": [{"role": "system", "content": "You are k8s-sre, a virtual Kubernetes engineer specialized on this cluster. Given the incident context, state the fix that worked and why, briefly."}, {"role": "user", "content": "[prod-east] alert_log: risk_level=CRITICAL pod=pricing-engine-2c524789-135d4 ns=inventory. kubernetes_pod_status: phase=Running ready=false restart_count=25. kubernetes_events: type=Warning reason=Failed count=48 message=\"Failed to pull image: manifest unknown\". What is happening and what is the fix?"}, {"role": "assistant", "content": "ImagePullBackOff on pricing-engine: the tag referenced by the deployment does not exist in the registry \u2014 fix the image tag (or push the missing tag) and the kubelet retries automatically."}]}
{"messages": [{"role": "system", "content": "You are k8s-sre, a virtual Kubernetes engineer specialized on this cluster. Given the incident context, state the fix that worked and why, briefly."}, {"role": "user", "content": "[prod-east] alert_log: risk_level=HIGH pod=notify-worker-689be22-7425 ns=payments. kubernetes_pod_status: phase=Running ready=false restart_count=33. kubernetes_events: type=Warning reason=FailedScheduling count=47 message=\"0/6 nodes are available: insufficient memory\". What is happening and what is the fix?"}, {"role": "assistant", "content": "FailedScheduling on notify-worker: requests exceed free node capacity \u2014 right-size the requests of notify-worker or add a node; check `kubectl describe pod` Events for the exact predicate that failed."}]}
{"messages": [{"role": "system", "content": "You are k8s-sre, a virtual Kubernetes engineer specialized on this cluster. Given the incident context, state the fix that worked and why, briefly."}, {"role": "user", "content": "[staging] alert_log: risk_level=CRITICAL pod=auth-gateway-399ea6dd-13874 ns=auth. kubernetes_pod_status: phase=Running ready=false restart_count=3. kubernetes_events: type=Warning reason=Unhealthy count=87 message=\"Readiness probe failed: HTTP probe failed with statuscode: 503\". What is happening and what is the fix?"}, {"role": "assistant", "content": "Unhealthy on auth-gateway: the app answers 503 during warmup \u2014 lengthen initialDelaySeconds/failureThreshold on the readiness probe so the rollout stops flapping the endpoint in and out."}]}
{"messages": [{"role": "system", "content": "You are k8s-sre, a virtual Kubernetes engineer specialized on this cluster. Given the incident context, state the fix that worked and why, briefly."}, {"role": "user", "content": "[prod-east] alert_log: risk_level=CRITICAL pod=notify-worker-356ae2d3-15238 ns=notifications. kubernetes_pod_status: phase=Running ready=false restart_count=10. kubernetes_events: type=Warning reason=FailedMount count=29 message=\"MountVolume.SetUp failed: secret not found\". What is happening and what is the fix?"}, {"role": "assistant", "content": "FailedMount on notify-worker: the pod references a secret that is absent in this namespace \u2014 create/copy the secret or fix the volume's secretName; the kubelet mounts it on the next sync."}]}
{"messages": [{"role": "system", "content": "You are k8s-sre, a virtual Kubernetes engineer specialized on this cluster. Given the incident context, state the fix that worked and why, briefly."}, {"role": "user", "content": "[prod-west] alert_log: risk_level=HIGH pod=pricing-engine-328131e7-1458d ns=checkout. kubernetes_pod_status: phase=Running ready=false restart_count=24. kubernetes_events: type=Warning reason=NodeNotReady count=54 message=\"Node is not ready: PLEG is not healthy\". What is happening and what is the fix?"}, {"role": "assistant", "content": "NodeNotReady on pricing-engine: the node's runtime is wedged \u2014 cordon + drain it, restart the container runtime (or reboot), and uncordon once Ready; pods reschedule automatically."}]}
{"messages": [{"role": "system", "content": "You are k8s-sre, a virtual Kubernetes engineer specialized on this cluster. Given the incident context, state the fix that worked and why, briefly."}, {"role": "user", "content": "[staging] alert_log: risk_level=HIGH pod=pricing-engine-56f5123-17318 ns=auth. kubernetes_pod_status: phase=Running ready=false restart_count=13. kubernetes_events: type=Warning reason=Evicted count=20 message=\"The node was low on resource: ephemeral-storage\". What is happening and what is the fix?"}, {"role": "assistant", "content": "Evicted on pricing-engine: ephemeral-storage pressure evicted the pod \u2014 clear image/log disk on the node and add an ephemeral-storage request to pricing-engine so the scheduler places it where space exists."}]}
{"messages": [{"role": "system", "content": "You are k8s-sre, a virtual Kubernetes engineer specialized on this cluster. Given the incident context, state the fix that worked and why, briefly."}, {"role": "user", "content": "[staging] alert_log: risk_level=MEDIUM pod=payments-api-39e918c2-ee42 ns=checkout. kubernetes_pod_status: phase=Running ready=false restart_count=12. kubernetes_events: type=Warning reason=BackOff count=80 message=\"Back-off restarting failed container\". What is happening and what is the fix?"}, {"role": "assistant", "content": "CrashLoopBackOff on payments-api: container exits on a failed dependency \u2014 read `kubectl logs --previous` for the exit reason, fix the dependency, then `kubectl rollout restart deploy/payments-api`."}]}
{"messages": [{"role": "system", "content": "You are k8s-sre, a virtual Kubernetes engineer specialized on this cluster. Given the incident context, state the fix that worked and why, briefly."}, {"role": "user", "content": "[prod-west] alert_log: risk_level=HIGH pod=pricing-engine-9fa781b-118e9 ns=notifications. kubernetes_pod_status: phase=Running ready=false restart_count=38. kubernetes_events: type=Warning reason=OOMKilling count=6 message=\"Memory cgroup out of memory: Killed process\". What is happening and what is the fix?"}, {"role": "assistant", "content": "OOMKilled on pricing-engine: memory limit is below the working set \u2014 raise the limit (and request) on pricing-engine, then watch `restart_count` return to 0; if growth continues it is a leak, not sizing."}]}
{"messages": [{"role": "system", "content": "You are k8s-sre, a virtual Kubernetes engineer specialized on this cluster. Given the incident context, state the fix that worked and why, briefly."}, {"role": "user", "content": "[staging] alert_log: risk_level=CRITICAL pod=payments-api-693d13e-10d9c ns=notifications. kubernetes_pod_status: phase=Running ready=false restart_count=11. kubernetes_events: type=Warning reason=Failed count=28 message=\"Failed to pull image: manifest unknown\". What is happening and what is the fix?"}, {"role": "assistant", "content": "ImagePullBackOff on payments-api: the tag referenced by the deployment does not exist in the registry \u2014 fix the image tag (or push the missing tag) and the kubelet retries automatically."}]}
{"messages": [{"role": "system", "content": "You are k8s-sre, a virtual Kubernetes engineer specialized on this cluster. Given the incident context, state the fix that worked and why, briefly."}, {"role": "user", "content": "[prod-west] alert_log: risk_level=HIGH pod=auth-gateway-d9e2f23-95ff ns=payments. kubernetes_pod_status: phase=Running ready=false restart_count=35. kubernetes_events: type=Warning reason=FailedScheduling count=79 message=\"0/6 nodes are available: insufficient memory\". What is happening and what is the fix?"}, {"role": "assistant", "content": "FailedScheduling on auth-gateway: requests exceed free node capacity \u2014 right-size the requests of auth-gateway or add a node; check `kubectl describe pod` Events for the exact predicate that failed."}]}
{"messages": [{"role": "system", "content": "You are k8s-sre, a virtual Kubernetes engineer specialized on this cluster. Given the incident context, state the fix that worked and why, briefly."}, {"role": "user", "content": "[staging] alert_log: risk_level=MEDIUM pod=notify-worker-1ad11a01-431c ns=inventory. kubernetes_pod_status: phase=Running ready=false restart_count=6. kubernetes_events: type=Warning reason=Unhealthy count=49 message=\"Readiness probe failed: HTTP probe failed with statuscode: 503\". What is happening and what is the fix?"}, {"role": "assistant", "content": "Unhealthy on notify-worker: the app answers 503 during warmup \u2014 lengthen initialDelaySeconds/failureThreshold on the readiness probe so the rollout stops flapping the endpoint in and out."}]}
{"messages": [{"role": "system", "content": "You are k8s-sre, a virtual Kubernetes engineer specialized on this cluster. Given the incident context, state the fix that worked and why, briefly."}, {"role": "user", "content": "[staging] alert_log: risk_level=MEDIUM pod=pricing-engine-3429bb05-10894 ns=notifications. kubernetes_pod_status: phase=Running ready=false restart_count=29. kubernetes_events: type=Warning reason=FailedMount count=20 message=\"MountVolume.SetUp failed: secret not found\". What is happening and what is the fix?"}, {"role": "assistant", "content": "FailedMount on pricing-engine: the pod references a secret that is absent in this namespace \u2014 create/copy the secret or fix the volume's secretName; the kubelet mounts it on the next sync."}]}
{"messages": [{"role": "system", "content": "You are k8s-sre, a virtual Kubernetes engineer specialized on this cluster. Given the incident context, state the fix that worked and why, briefly."}, {"role": "user", "content": "[staging] alert_log: risk_level=MEDIUM pod=inventory-sync-13275e3-e158 ns=search. kubernetes_pod_status: phase=Running ready=false restart_count=14. kubernetes_events: type=Warning reason=NodeNotReady count=4 message=\"Node is not ready: PLEG is not healthy\". What is happening and what is the fix?"}, {"role": "assistant", "content": "NodeNotReady on inventory-sync: the node's runtime is wedged \u2014 cordon + drain it, restart the container runtime (or reboot), and uncordon once Ready; pods reschedule automatically."}]}
{"messages": [{"role": "system", "content": "You are k8s-sre, a virtual Kubernetes engineer specialized on this cluster. Given the incident context, state the fix that worked and why, briefly."}, {"role": "user", "content": "[prod-east] alert_log: risk_level=MEDIUM pod=inventory-sync-1e4db54d-13cfa ns=checkout. kubernetes_pod_status: phase=Running ready=false restart_count=10. kubernetes_events: type=Warning reason=Evicted count=11 message=\"The node was low on resource: ephemeral-storage\". What is happening and what is the fix?"}, {"role": "assistant", "content": "Evicted on inventory-sync: ephemeral-storage pressure evicted the pod \u2014 clear image/log disk on the node and add an ephemeral-storage request to inventory-sync so the scheduler places it where space exists."}]}
{"messages": [{"role": "system", "content": "You are k8s-sre, a virtual Kubernetes engineer specialized on this cluster. Given the incident context, state the fix that worked and why, briefly."}, {"role": "user", "content": "[staging] alert_log: risk_level=HIGH pod=notify-worker-21f76bad-11c62 ns=notifications. kubernetes_pod_status: phase=Running ready=false restart_count=33. kubernetes_events: type=Warning reason=BackOff count=75 message=\"Back-off restarting failed container\". What is happening and what is the fix?"}, {"role": "assistant", "content": "CrashLoopBackOff on notify-worker: container exits on a failed dependency \u2014 read `kubectl logs --previous` for the exit reason, fix the dependency, then `kubectl rollout restart deploy/notify-worker`."}]}
{"messages": [{"role": "system", "content": "You are k8s-sre, a virtual Kubernetes engineer specialized on this cluster. Given the incident context, state the fix that worked and why, briefly."}, {"role": "user", "content": "[prod-east] alert_log: risk_level=MEDIUM pod=payments-api-11b90264-159b ns=checkout. kubernetes_pod_status: phase=Running ready=false restart_count=9. kubernetes_events: type=Warning reason=OOMKilling count=61 message=\"Memory cgroup out of memory: Killed process\". What is happening and what is the fix?"}, {"role": "assistant", "content": "OOMKilled on payments-api: memory limit is below the working set \u2014 raise the limit (and request) on payments-api, then watch `restart_count` return to 0; if growth continues it is a leak, not sizing."}]}
{"messages": [{"role": "system", "content": "You are k8s-sre, a virtual Kubernetes engineer specialized on this cluster. Given the incident context, state the fix that worked and why, briefly."}, {"role": "user", "content": "[prod-west] alert_log: risk_level=MEDIUM pod=payments-api-14d6da90-1399d ns=payments. kubernetes_pod_status: phase=Running ready=false restart_count=35. kubernetes_events: type=Warning reason=Failed count=69 message=\"Failed to pull image: manifest unknown\". What is happening and what is the fix?"}, {"role": "assistant", "content": "ImagePullBackOff on payments-api: the tag referenced by the deployment does not exist in the registry \u2014 fix the image tag (or push the missing tag) and the kubelet retries automatically."}]}
{"messages": [{"role": "system", "content": "You are k8s-sre, a virtual Kubernetes engineer specialized on this cluster. Given the incident context, state the fix that worked and why, briefly."}, {"role": "user", "content": "[prod-west] alert_log: risk_level=CRITICAL pod=auth-gateway-1cf33bc0-1042d ns=notifications. kubernetes_pod_status: phase=Running ready=false restart_count=37. kubernetes_events: type=Warning reason=FailedScheduling count=68 message=\"0/6 nodes are available: insufficient memory\". What is happening and what is the fix?"}, {"role": "assistant", "content": "FailedScheduling on auth-gateway: requests exceed free node capacity \u2014 right-size the requests of auth-gateway or add a node; check `kubectl describe pod` Events for the exact predicate that failed."}]}
{"messages": [{"role": "system", "content": "You are k8s-sre, a virtual Kubernetes engineer specialized on this cluster. Given the incident context, state the fix that worked and why, briefly."}, {"role": "user", "content": "[staging] alert_log: risk_level=HIGH pod=auth-gateway-38192845-84e9 ns=notifications. kubernetes_pod_status: phase=Running ready=false restart_count=38. kubernetes_events: type=Warning reason=Unhealthy count=61 message=\"Readiness probe failed: HTTP probe failed with statuscode: 503\". What is happening and what is the fix?"}, {"role": "assistant", "content": "Unhealthy on auth-gateway: the app answers 503 during warmup \u2014 lengthen initialDelaySeconds/failureThreshold on the readiness probe so the rollout stops flapping the endpoint in and out."}]}
{"messages": [{"role": "system", "content": "You are k8s-sre, a virtual Kubernetes engineer specialized on this cluster. Given the incident context, state the fix that worked and why, briefly."}, {"role": "user", "content": "[prod-east] alert_log: risk_level=HIGH pod=inventory-sync-191c7f79-e25d ns=auth. kubernetes_pod_status: phase=Running ready=false restart_count=23. kubernetes_events: type=Warning reason=FailedMount count=89 message=\"MountVolume.SetUp failed: secret not found\". What is happening and what is the fix?"}, {"role": "assistant", "content": "FailedMount on inventory-sync: the pod references a secret that is absent in this namespace \u2014 create/copy the secret or fix the volume's secretName; the kubelet mounts it on the next sync."}]}
{"messages": [{"role": "system", "content": "You are k8s-sre, a virtual Kubernetes engineer specialized on this cluster. Given the incident context, state the fix that worked and why, briefly."}, {"role": "user", "content": "[prod-east] alert_log: risk_level=HIGH pod=auth-gateway-d9cb5ab-156c5 ns=auth. kubernetes_pod_status: phase=Running ready=false restart_count=22. kubernetes_events: type=Warning reason=NodeNotReady count=23 message=\"Node is not ready: PLEG is not healthy\". What is happening and what is the fix?"}, {"role": "assistant", "content": "NodeNotReady on auth-gateway: the node's runtime is wedged \u2014 cordon + drain it, restart the container runtime (or reboot), and uncordon once Ready; pods reschedule automatically."}]}
{"messages": [{"role": "system", "content": "You are k8s-sre, a virtual Kubernetes engineer specialized on this cluster. Given the incident context, state the fix that worked and why, briefly."}, {"role": "user", "content": "[prod-west] alert_log: risk_level=HIGH pod=notify-worker-38805548-4646 ns=checkout. kubernetes_pod_status: phase=Running ready=false restart_count=32. kubernetes_events: type=Warning reason=Evicted count=16 message=\"The node was low on resource: ephemeral-storage\". What is happening and what is the fix?"}, {"role": "assistant", "content": "Evicted on notify-worker: ephemeral-storage pressure evicted the pod \u2014 clear image/log disk on the node and add an ephemeral-storage request to notify-worker so the scheduler places it where space exists."}]}
{"messages": [{"role": "system", "content": "You are k8s-sre, a virtual Kubernetes engineer specialized on this cluster. Given the incident context, state the fix that worked and why, briefly."}, {"role": "user", "content": "[prod-east] alert_log: risk_level=MEDIUM pod=orders-consumer-2abdc67c-728a ns=auth. kubernetes_pod_status: phase=Running ready=false restart_count=13. kubernetes_events: type=Warning reason=BackOff count=59 message=\"Back-off restarting failed container\". What is happening and what is the fix?"}, {"role": "assistant", "content": "CrashLoopBackOff on orders-consumer: container exits on a failed dependency \u2014 read `kubectl logs --previous` for the exit reason, fix the dependency, then `kubectl rollout restart deploy/orders-consumer`."}]}
{"messages": [{"role": "system", "content": "You are k8s-sre, a virtual Kubernetes engineer specialized on this cluster. Given the incident context, state the fix that worked and why, briefly."}, {"role": "user", "content": "[prod-west] alert_log: risk_level=HIGH pod=orders-consumer-c8714a5-b696 ns=inventory. kubernetes_pod_status: phase=Running ready=false restart_count=23. kubernetes_events: type=Warning reason=OOMKilling count=50 message=\"Memory cgroup out of memory: Killed process\". What is happening and what is the fix?"}, {"role": "assistant", "content": "OOMKilled on orders-consumer: memory limit is below the working set \u2014 raise the limit (and request) on orders-consumer, then watch `restart_count` return to 0; if growth continues it is a leak, not sizing."}]}
{"messages": [{"role": "system", "content": "You are k8s-sre, a virtual Kubernetes engineer specialized on this cluster. Given the incident context, state the fix that worked and why, briefly."}, {"role": "user", "content": "[staging] alert_log: risk_level=CRITICAL pod=payments-api-1d5adca2-e183 ns=inventory. kubernetes_pod_status: phase=Running ready=false restart_count=4. kubernetes_events: type=Warning reason=Failed count=46 message=\"Failed to pull image: manifest unknown\". What is happening and what is the fix?"}, {"role": "assistant", "content": "ImagePullBackOff on payments-api: the tag referenced by the deployment does not exist in the registry \u2014 fix the image tag (or push the missing tag) and the kubelet retries automatically."}]}
{"messages": [{"role": "system", "content": "You are k8s-sre, a virtual Kubernetes engineer specialized on this cluster. Given the incident context, state the fix that worked and why, briefly."}, {"role": "user", "content": "[prod-east] alert_log: risk_level=HIGH pod=search-indexer-738ef03-7505 ns=search. kubernetes_pod_status: phase=Running ready=false restart_count=9. kubernetes_events: type=Warning reason=FailedScheduling count=37 message=\"0/6 nodes are available: insufficient memory\". What is happening and what is the fix?"}, {"role": "assistant", "content": "FailedScheduling on search-indexer: requests exceed free node capacity \u2014 right-size the requests of search-indexer or add a node; check `kubectl describe pod` Events for the exact predicate that failed."}]}
